Workbook

Sheet Read me
A1: Big Brother data: proofreading sheet
A2: Generated 2026-10-25T17:24:33+00:00 from the Wikipedia and Big Brother Wiki pages cached in this repo. Adapted from Wikipedia (CC BY-SA 4.0) and the Big Brother Wiki (CC BY-SA 3.0); this workbook is licensed CC BY-SA 4.0 (https://creativecommons.org/licenses/by-sa/4.0/).
A4: How to proofread
A5: Only the yellow columns are for you: set “Looks right?” to OK, Wrong or Unsure, and write what should change in “Correction”.
A6: Example: on Weeks, BB26 · Week 4, you might set Wrong and write “Veto use should say Tucker used it on himself”.
A7: Every row has a Source link to the exact revision the data came from: Wikipedia, or the Big Brother Wiki (bigbrother.fandom.com) on the BB Wiki tabs.
A8: Filters are on every header row; shaded Weeks rows are weeks that aren’t plain evictions.
A10: Tabs
A11: Weeks (114 rows): one row per eviction round — HOH, noms, veto, twist rows, final noms, evicted, tally, plus the HOH/veto competition names and what the veto did.
A12: Votes (1112 rows): every houseguest’s vote in every round, or why they didn’t vote. “With the house” is a formula.
A13: Players (131 rows): totals are COUNTIFS formulas over Weeks and Votes, so fixing a week there updates them.
A14: Competitions (150 rows): competition names found in the episode summaries, with the sentence each came from.
... A25: Player totals: count only the rounds the grid models (twist rounds shown as notes are left out).

Sheet Weeks
A1: Season | B1: Week | C1: Round | D1: Status | E1: Note | F1: HOH | G1: HOH comp | H1: Noms | I1: Veto | J1: Veto comp | K1: Veto use | L1: Twist rows | M1: Final noms | N1: Evicted | O1: Tally | P1: Source | Q1: Looks right? | R1: Correction | S1: hoh_key | T1: veto_key | U1: noms_key | V1: final_key | W1: twist_key
A2: BB28 | B2: Week 1 | D2: ok | F2: Dee | G2: 175 Million BC | H2: Mallory, Taylor, Yash | I2: Mallory | J2: Back From the Future | K2: Used on Mallory (themselves); replacement: Ashley; Yash saved by a twist | L2: Block Buster winner: Yash | M2: Ashley, Taylor | N2: Ashley | O2: 14 of 14 votes to evict | P2: Wikipedia | S2: ;Dee; | T2: ;Mallory; | U2: ;Mallory;Taylor;Yash; | V2: ;Ashley;Taylor; | W2: ;Yash;
A3: BB28 | B3: Week 2 | D3: ok | F3: Devens | G3: Achy Breaky HOH | H3: Jason, Lyric, Melody | I3: Devens | J3: Flower Power | K3: Used on Lyric; replacement: Rome; Jason saved by a twist | L3: Block Buster winner: Jason | M3: Melody, Rome | N3: Rome | O3: 12 of 13 votes to evict | P3: Wikipedia | S3: ;Devens; | T3: ;Devens; | U3: ;Jason;Lyric;Melody; | V3: ;Melody;Rome; | W3: ;Jason;
A4: BB28 | B4: Week 3 | D4: ok | F4: Kamu | G4: Wrestlegasm 85 | H4: La Trice, Lyric, Mallory | I4: Lyric | J4: The Pickle Ball | K4: Used on Lyric (themselves); replacement: Jason; Mallory saved by a twist | L4: Block Buster winner: Mallory | M4: Jason, La Trice | N4: Jason | O4: 12 of 12 votes to evict | P4: Wikipedia | S4: ;Kamu; | T4: ;Lyric; | U4: ;La Trice;Lyric;Mallory; | V4: ;Jason;La Trice; | W4: ;Mallory;
A5: BB28 | B5: Week 4 | D5: ok | F5: Haley | G5: Jack the Ripper | H5: Drew, Melody, Taylor | I5: Taylor | J5: Murder at the Masquerade | K5: Used on Taylor (themselves); replacement: Lyric; Drew saved by a twist | L5: Block Buster winner: Drew | M5: Lyric, Melody | N5: Lyric | O5: 8 of 11 votes to evict | P5: Wikipedia | S5: ;Haley; | T5: ;Taylor; | U5: ;Drew;Melody;Taylor; | V5: ;Lyric;Melody; | W5: ;Drew;
A6: BB28 | B6: Week 5 | D6: ok | F6: La Trice | G6: Sasquatch Watch | H6: Barrett, Chuk, Haley | I6: Kamu | J6: Saturday Night Veto | K6: Not used; Haley saved by a twist | L6: Block Buster winner: Haley | M6: Barrett, Chuk | N6: Chuk | O6: 9 of 10 votes to evict | P6: Wikipedia | S6: ;La Trice; | T6: ;Kamu; | U6: ;Barrett;Chuk;Haley; | V6: ;Barrett;Chuk; | W6: ;Haley;
A7: BB28 | B7: Week 6 | D7: ok | F7: Yash | G7: Bugs in the System | H7: Angela, Dee, Haley | I7: Yash, Devens | J7: OTEV the Belligerent B-Movie Blob | K7: Used on Dee; replacement: Kamu; Angela saved by a twist | L7: Block Buster winner: Angela | M7: Haley, Kamu | N7: Kamu | O7: 8 of 9 votes to evict | P7: Wikipedia | S7: ;Yash; | T7: ;Yash;Devens; | U7: ;Angela;Dee;Haley; | V7: ;Haley;Kamu; | W7: ;Angela;
A8: BB28 | B8: Week 7 | D8: ok | F8: Dee | G8: Norse By Norsewest | H8: Drew, La Trice, Taylor | I8: La Trice | J8: Feel The Burn | K8: Used on La Trice (themselves); replacement: Mallory; Drew saved by a twist | L8: Block Buster winner: Drew | M8: Mallory, Taylor | N8: Mallory | O8: 6 of 8 votes to evict | P8: Wikipedia | S8: ;Dee; | T8: ;La Trice; | U8: ;Drew;La Trice;Taylor; | V8: ;Mallory;Taylor; | W8: ;Drew;
A9: BB28 | B9: Week 8 | C9: Day 53 | D9: note | E9: Two rounds: Day 52 / Day 53; Round 1 (Day 52): Non-standard outcome: Haley Yash's choice to eliminate | F9: Drew | G9: 2026: A Zing Odyssey | H9: La Trice, Taylor, Yash | I9: Yash | J9: The Gold, the Bad, and the Ugly | K9: Used on Yash (themselves) | L9: Block Buster winner: Devens | M9: La Trice, Taylor | N9: La Trice | O9: 4 of 6 votes to evict | P9: Wikipedia | S9: ;Drew; | T9: ;Yash; | U9: ;La Trice;Taylor;Yash; | V9: ;La Trice;Taylor; | W9: ;Devens;
A10: BB28 | B10: Week 9 | D10: ok | F10: Barrett | G10: Rainbow Rollers | H10: Angela, Dee, Devens | I10: Yash | J10: BB Comics | K10: Not used; Devens saved by a twist | L10: Block Buster winner: Devens | M10: Angela, Dee | N10: Angela | O10: 3 of 5 votes to evict | P10: Wikipedia | S10: ;Barrett; | T10: ;Yash; | U10: ;Angela;Dee;Devens; | V10: ;Angela;Dee; | W10: ;Devens;
A11: BB28 | B11: Week 10 | C11: Day 67 | D11: ok | E11: Double eviction | F11: Yash | G11: Wet and Wild West | H11: Barrett, Drew, Melody | I11: Drew | J11: Circle of Trust | K11: Used on Drew (themselves); replacement: Taylor; Melody saved by a twist | L11: Block Buster winner: Melody | M11: Barrett, Taylor | N11: Barrett | O11: 3 of 4 votes to evict | P11: Wikipedia | S11: ;Yash; | T11: ;Drew; | U11: ;Barrett;Drew;Melody; | V11: ;Barrett;Taylor; | W11: ;Melody;
A12: BB28 | B12: Week 10 | C12: Day 73 | D12: ok | E12: Double eviction | F12: Melody | G12: Bleeping Through Time | H12: Dee, Devens | I12: Devens | J12: Great Ball of China | K12: Used on Devens (themselves); replacement: Yash | M12: Dee, Yash | N12: Yash | O12: 2 of 3 votes to evict | P12: Wikipedia | S12: ;Melody; | T12: ;Devens; | U12: ;Dee;Devens; | V12: ;Dee;Yash;
A13: BB28 | B13: Week 11 | C13: Day 74 | D13: ok | E13: Two evictions | F13: Devens | G13: Reverse the Curse | H13: Drew, Melody | I13: Drew | J13: Block Like an Egyptian | K13: Used on Drew (themselves); replacement: Taylor | M13: Melody, Taylor | N13: Melody | O13: 2 of 3 votes to evict | P13: Wikipedia | S13: ;Devens; | T13: ;Drew; | U13: ;Drew;Melody; | V13: ;Melody;Taylor;
A14: BB28 | B14: Week 11 | C14: Day 77 | D14: ok | E14: Two evictions | F14: Taylor | G14: Eternally Yours | H14: Dee, Drew | I14: Drew | J14: Time Travel Toilet | K14: Used on Drew (themselves); replacement: Devens | M14: Dee, Devens | N14: Dee | O14: Drew's choice to evict | P14: Wikipedia | S14: ;Taylor; | T14: ;Drew; | U14: ;Dee;Drew; | V14: ;Dee;Devens;
A15: BB28 | B15: Week 12 | D15: note | E15: Finale; Non-standard outcome: Drew Devens' choice to evict | P15: Wikipedia
A16: BB27 | B16: Week 1 | D16: ok | F16: Vince | G16: Destroy the Lair | H16: Amy, Ashley, Zae | I16: Ashley | J16: Campsite Caper | K16: Used on Ashley (themselves) | L16: Block Buster winner: Kelley | M16: Amy, Zae | N16: Zae | O16: 9 of 14 votes to evict | P16: Wikipedia | S16: ;Vince; | T16: ;Ashley; | U16: ;Amy;Ashley;Zae; | V16: ;Amy;Zae; | W16: ;Kelley;
A17: BB27 | B17: Week 2 | D17: ok | F17: Jimmy | G17: BB Break In | H17: Adrian, Keanu, Kelley | I17: Keanu, Kelley | J17: Caught Creepin | K17: Used on Keanu, Kelley (themselves); replacement: Amy, Will; Adrian saved by a twist | L17: Block Buster winner: Adrian | M17: Amy, Will | N17: Amy | O17: 13 of 13 votes to evict | P17: Wikipedia | S17: ;Jimmy; | T17: ;Keanu;Kelley; | U17: ;Adrian;Keanu;Kelley; | V17: ;Amy;Will; | W17: ;Adrian;
A18: BB27 | B18: Week 3 | D18: ok | F18: Lauren | G18: Twin Witness News | H18: Keanu, Kelley, Will | I18: Keanu | J18: Basement Break In | K18: Used on Keanu (themselves); replacement: Adrian; Kelley saved by a twist | L18: Block Buster winner: Kelley | M18: Adrian, Will | N18: Adrian | O18: 8 of 12 votes to evict | P18: Wikipedia | S18: ;Lauren; | T18: ;Keanu; | U18: ;Keanu;Kelley;Will; | V18: ;Adrian;Will; | W18: ;Kelley;
A19: BB27 | B19: Week 4 | D19: ok | F19: Rylie, Mickey | G19: Killer Carnival | H19: Keanu, Kelley, Rylie | I19: Keanu | J19: Flee the Scene | K19: Used on Keanu (themselves); replacement: Jimmy; Rylie saved by a twist | L19: Block Buster winner: Rylie | M19: Jimmy, Kelley | N19: Jimmy | O19: 9 of 11 votes to evict | P19: Wikipedia | S19: ;Rylie;Mickey; | T19: ;Keanu; | U19: ;Keanu;Kelley;Rylie; | V19: ;Jimmy;Kelley; | W19: ;Rylie;
A20: BB27 | B20: Week 5 | D20: ok | F20: Ava | G20: Jack the Dipper | H20: Keanu, Vince, Zach | I20: Katherine | J20: Elusive Target | K20: Not used; Keanu saved by a twist | L20: Block Buster winner: Keanu | M20: Vince, Zach | N20: Zach | O20: 8 of 10 votes to evict | P20: Wikipedia | S20: ;Ava; | T20: ;Katherine; | U20: ;Keanu;Vince;Zach; | V20: ;Vince;Zach; | W20: ;Keanu;
A21: BB27 | B21: Week 6 | D21: ok | F21: Rachel | G21: The Party Slasher | H21: Mickey, Morgan, Vince | I21: Lauren | J21: OTEV the Hog Father | K21: Used on Vince; replacement: Rylie; Mickey saved by a twist | L21: Block Buster winner: Mickey | M21: Morgan, Rylie | N21: Rylie | O21: 5 of 9 votes to evict | P21: Wikipedia | S21: ;Rachel; | T21: ;Lauren; | U21: ;Mickey;Morgan;Vince; | V21: ;Morgan;Rylie; | W21: ;Mickey;
A22: BB27 | B22: Week 7 | D22: ok | F22: Vince | G22: Mystere Express | H22: Ava, Kelley, Mickey | I22: Mickey | J22: Wine to Die For | K22: Used on Mickey (themselves); replacement: Katherine; Kelley saved by a twist | L22: Block Buster winner: Kelley | M22: Ava, Katherine | N22: Katherine | O22: 7 of 8 votes to evict | P22: Wikipedia | S22: ;Vince; | T22: ;Mickey; | U22: ;Ava;Kelley;Mickey; | V22: ;Ava;Katherine; | W22: ;Kelley;
A23: BB27 | B23: Week 8 | D23: ok | F23: Keanu | G23: Mystere Moments | H23: Mickey, Morgan, Vince | I23: Morgan | J23: Charcuterie Protection Agency | K23: Used on Morgan (themselves); replacement: Ashley; Vince saved by a twist | L23: Block Buster winner: Vince | M23: Ashley, Mickey | N23: Mickey | O23: 6 of 7 votes to evict | P23: Wikipedia | S23: ;Keanu; | T23: ;Morgan; | U23: ;Mickey;Morgan;Vince; | V23: ;Ashley;Mickey; | W23: ;Vince;
A24: BB27 | B24: Week 9 | C24: Day 60 | D24: note | E24: Two rounds: Day 59 / Day 60; Round 1 (Day 59): Non-standard outcome: Rachel Eliminated by competition | F24: Lauren | G24: Mastermind's Maniacal Maze | H24: Ashley, Morgan, Will | I24: Morgan | J24: BB Comics | K24: Used on Morgan (themselves) | L24: Block Buster winner: Keanu | M24: Ashley, Will | N24: Will | O24: 3 of 5 votes to evict | P24: Wikipedia | S24: ;Lauren; | T24: ;Morgan; | U24: ;Ashley;Morgan;Will; | V24: ;Ashley;Will; | W24: ;Keanu;
A25: BB27 | B25: Week 10 | C25: Day 67 | D25: ok | E25: Double eviction | F25: Vince | G25: The Last Zing: The True Story of Zingbot's Demise | H25: Ava, Keanu, Kelley | I25: Morgan | J25: BB CSI | K25: Used on Ava | L25: Block Buster winner: Lauren | M25: Keanu, Kelley | N25: Kelley | O25: 3 of 5 votes to evict | P25: Wikipedia | S25: ;Vince; | T25: ;Morgan; | U25: ;Ava;Keanu;Kelley; | V25: ;Keanu;Kelley; | W25: ;Lauren;
A26: BB27 | B26: Week 10 | C26: Day 73 | D26: ok | E26: Double eviction | F26: Morgan | G26: Wretched Reactor | H26: Keanu, Lauren | I26: Keanu | J26: Masterfind | K26: Used on Keanu (themselves); replacement: Ava | M26: Ava, Lauren | N26: Lauren | O26: 2 of 3 votes to evict | P26: Wikipedia | S26: ;Morgan; | T26: ;Keanu; | U26: ;Keanu;Lauren; | V26: ;Ava;Lauren;
A27: BB27 | B27: Week 11 | C27: Day 74 | D27: ok | E27: Two evictions | F27: Vince | G27: Torturous Trial | H27: Ava, Keanu | I27: Morgan | J27: Masterpieces | K27: Not used | M27: Ava, Keanu | N27: Keanu | O27: 2 of 2 votes to evict | P27: Wikipedia | S27: ;Vince; | T27: ;Morgan; | U27: ;Ava;Keanu; | V27: ;Ava;Keanu;
A28: BB27 | B28: Week 11 | C28: Day 77 | D28: ok | E28: Two evictions | F28: Morgan | G28: ForensiScope | H28: Ashley, Ava | I28: Morgan | J28: Organized Crime | K28: Not used | M28: Ashley, Ava | N28: Ava | O28: Vince's choice to evict | P28: Wikipedia | S28: ;Morgan; | T28: ;Morgan; | U28: ;Ashley;Ava; | V28: ;Ashley;Ava;
A29: BB27 | B29: Week 12 | C29: Day 83 | D29: note | E29: Finale | F29: Ashley | G29: Unmask the Mastermind | M29: Morgan, Vince | N29: Morgan | O29: Ashley's choice to evict | P29: Wikipedia | S29: ;Ashley; | V29: ;Morgan;Vince;
A30: BB26 | B30: Week 1 | D30: ok | F30: Angela | G30: New Rule | H30: Kenney, Kimo, Lisa | I30: Lisa | J30: BB AI Spelling Bee | K30: Used on Lisa (themselves); replacement: Matt; Kimo saved by a twist | L30: AI Arena winner: Kimo | M30: Kenney, Matt | N30: Matt | O30: 8 of 11 votes to evict | P30: Wikipedia | S30: ;Angela; | T30: ;Lisa; | U30: ;Kenney;Kimo;Lisa; | V30: ;Kenney;Matt; | W30: ;Kimo;
A31: BB26 | B31: Week 2 | D31: ok | F31: Chelsie | G31: Animal Obsession | H31: Angela, Kenney, Lisa | I31: Kenney | J31: Code Tower | K31: Used on Kenney (themselves) | L31: AI Arena winner: Tucker | M31: Angela, Lisa | N31: Lisa | O31: 11 of 12 votes to evict | P31: Wikipedia | S31: ;Chelsie; | T31: ;Kenney; | U31: ;Angela;Kenney;Lisa; | V31: ;Angela;Lisa; | W31: ;Tucker;
A32: BB26 | B32: Week 3 | D32: ok | F32: Cedric | G32: Ainsley Land | H32: Angela, Kenney, Tucker | I32: Tucker, Makensy | J32: Recharge My Core | K32: Used on Angela; replacement: Quinn; Tucker saved by a twist | L32: AI Arena winner: Tucker | M32: Kenney, Quinn | N32: Kenney | O32: 10 of 11 votes to evict | P32: Wikipedia | S32: ;Cedric; | T32: ;Tucker;Makensy; | U32: ;Angela;Kenney;Tucker; | V32: ;Kenney;Quinn; | W32: ;Tucker;
A33: BB26 | B33: Week 4 | D33: ok | F33: Angela, Quinn | G33: Bad AI | H33: Cedric, Makensy, Tucker | I33: Tucker | J33: Binary Bridge | K33: Used on Tucker (themselves); replacement: Rubina; Makensy saved by a twist | L33: AI Arena winner: Makensy | M33: Cedric, Rubina | N33: Cedric | O33: 6 of 9 votes to evict | P33: Wikipedia | S33: ;Angela;Quinn; | T33: ;Tucker; | U33: ;Cedric;Makensy;Tucker; | V33: ;Cedric;Rubina; | W33: ;Makensy;
A34: BB26 | B34: Week 5 | D34: ok | F34: Tucker | G34: Firewall | H34: Brooklyn, Cam, Quinn | I34: Tucker | J34: Hide-N-Go Veto | K34: Used on Quinn | L34: AI Arena winner: Chelsie | M34: Brooklyn, Cam | N34: Brooklyn | O34: 8 of 9 votes to evict | P34: Wikipedia | S34: ;Tucker; | T34: ;Tucker; | U34: ;Brooklyn;Cam;Quinn; | V34: ;Brooklyn;Cam; | W34: ;Chelsie;
A35: BB26 | B35: Week 6 | D35: ok | F35: T'kor | G35: Sound Bites | H35: Cam, Makensy, Tucker | I35: Cam | J35: A.I. Apocalypse | K35: Used on Cam (themselves); replacement: Angela; Makensy saved by a twist | L35: AI Arena winner: Makensy | M35: Angela, Tucker | N35: Tucker | O35: 5 of 8 votes to evict | P35: Wikipedia | S35: ;T'kor; | T35: ;Cam; | U35: ;Cam;Makensy;Tucker; | V35: ;Angela;Tucker; | W35: ;Makensy;
A36: BB26 | B36: Week 7 | D36: ok | F36: Quinn | G36: What Came First? | H36: Angela, Kimo, Rubina | I36: Leah | J36: Bot Builders | K36: Used on Angela; replacement: Joseph; Rubina saved by a twist | L36: AI Arena winner: Rubina | M36: Joseph, Kimo | N36: Joseph | O36: 4 of 7 votes to evict | P36: Wikipedia | S36: ;Quinn; | T36: ;Leah; | U36: ;Angela;Kimo;Rubina; | V36: ;Joseph;Kimo; | W36: ;Rubina;
A37: BB26 | B37: Week 8 | D37: ok | F37: Chelsie | G37: Ding Cam | H37: Angela, Kimo | I37: Makensy | J37: OTEV the Trash-Talking Trash Panda | K37: Used on Angela; replacement: Quinn | M37: Kimo, Quinn | N37: Quinn | O37: 4 of 6 votes to evict | P37: Wikipedia | S37: ;Chelsie; | T37: ;Makensy; | U37: ;Angela;Kimo; | V37: ;Kimo;Quinn;
A38: BB26 | B38: Week 9 | D38: ok | F38: Leah | G38: Getting Toasted | H38: Kimo, Rubina | I38: Angela, Leah | J38: Too Much of a Good Thing | K38: Used on Kimo; replacement: T'kor | M38: Rubina, T'kor | N38: T'kor | O38: 4 of 5 votes to evict | P38: Wikipedia | S38: ;Leah; | T38: ;Angela;Leah; | U38: ;Kimo;Rubina; | V38: ;Rubina;T'kor;
A39: BB26 | B39: Week 10 | C39: Day 67 | D39: ok | E39: Double eviction | F39: Makensy | G39: Eye Candy | H39: Angela, Kimo | I39: Makensy | J39: The Wild Robot | K39: Used on Kimo; replacement: Leah | M39: Angela, Leah | N39: Leah | O39: 4 of 4 votes to evict | P39: Wikipedia | S39: ;Makensy; | T39: ;Makensy; | U39: ;Angela;Kimo; | V39: ;Angela;Leah;
A40: BB26 | B40: Week 10 | C40: Day 73 | D40: ok | E40: Double eviction | F40: Chelsie | G40: Warning Messages | H40: Angela, Kimo | I40: Kimo | J40: Eye in the Sky | K40: Used on Kimo (themselves); replacement: Rubina | M40: Angela, Rubina | N40: Angela | O40: 3 of 3 votes to evict | P40: Wikipedia | S40: ;Chelsie; | T40: ;Kimo; | U40: ;Angela;Kimo; | V40: ;Angela;Rubina;
...

Sheet Votes
A1: Season | B1: Week | C1: Round | D1: Voter | E1: Voted to evict | F1: Didn't vote because | G1: Evicted | H1: With the house | I1: Source | J1: Looks right? | K1: Correction
A2: BB28 | B2: Week 1 | D2: Devens | E2: Ashley | G2: Ashley | H2: =IF(E2="","",IF(E2=G2,"Yes","No")) -> Yes | I2: Wikipedia
A3: BB28 | B3: Week 1 | D3: Drew | E3: Ashley | G3: Ashley | H3: =IF(E3="","",IF(E3=G3,"Yes","No")) -> Yes | I3: Wikipedia
A4: BB28 | B4: Week 1 | D4: Melody | E4: Ashley | G4: Ashley | H4: =IF(E4="","",IF(E4=G4,"Yes","No")) -> Yes | I4: Wikipedia
A5: BB28 | B5: Week 1 | D5: Yash | E5: Ashley | G5: Ashley | H5: =IF(E5="","",IF(E5=G5,"Yes","No")) -> Yes | I5: Wikipedia
A6: BB28 | B6: Week 1 | D6: Barrett | E6: Ashley | G6: Ashley | H6: =IF(E6="","",IF(E6=G6,"Yes","No")) -> Yes | I6: Wikipedia
A7: BB28 | B7: Week 1 | D7: Angela | E7: Ashley | G7: Ashley | H7: =IF(E7="","",IF(E7=G7,"Yes","No")) -> Yes | I7: Wikipedia
A8: BB28 | B8: Week 1 | D8: La Trice | E8: Ashley | G8: Ashley | H8: =IF(E8="","",IF(E8=G8,"Yes","No")) -> Yes | I8: Wikipedia
A9: BB28 | B9: Week 1 | D9: Haley | E9: Ashley | G9: Ashley | H9: =IF(E9="","",IF(E9=G9,"Yes","No")) -> Yes | I9: Wikipedia
A10: BB28 | B10: Week 1 | D10: Mallory | E10: Ashley | G10: Ashley | H10: =IF(E10="","",IF(E10=G10,"Yes","No")) -> Yes | I10: Wikipedia
A11: BB28 | B11: Week 1 | D11: Kamu | E11: Ashley | G11: Ashley | H11: =IF(E11="","",IF(E11=G11,"Yes","No")) -> Yes | I11: Wikipedia
A12: BB28 | B12: Week 1 | D12: Chuk | E12: Ashley | G12: Ashley | H12: =IF(E12="","",IF(E12=G12,"Yes","No")) -> Yes | I12: Wikipedia
A13: BB28 | B13: Week 1 | D13: Lyric | E13: Ashley | G13: Ashley | H13: =IF(E13="","",IF(E13=G13,"Yes","No")) -> Yes | I13: Wikipedia
... A15: BB28 | B15: Week 1 | D15: Rome | E15: Ashley | G15: Ashley | H15: =IF(E15="","",IF(E15=G15,"Yes","No")) -> Yes | I15: Wikipedia
A16: BB28 | B16: Week 1 | D16: Taylor | F16: Nominated | G16: Ashley | H16: =IF(E16="","",IF(E16=G16,"Yes","No")) | I16: Wikipedia
A17: BB28 | B17: Week 1 | D17: Dee | F17: Head of Household | G17: Ashley | H17: =IF(E17="","",IF(E17=G17,"Yes","No")) | I17: Wikipedia
A18: BB28 | B18: Week 1 | D18: Ashley | F18: Nominated | G18: Ashley | H18: =IF(E18="","",IF(E18=G18,"Yes","No")) | I18: Wikipedia
A19: BB28 | B19: Week 2 | D19: Taylor | E19: Melody | G19: Rome | H19: =IF(E19="","",IF(E19=G19,"Yes","No")) -> No | I19: Wikipedia
A20: BB28 | B20: Week 2 | D20: Drew | E20: Rome | G20: Rome | H20: =IF(E20="","",IF(E20=G20,"Yes","No")) -> Yes | I20: Wikipedia
A21: BB28 | B21: Week 2 | D21: Dee | E21: Rome | G21: Rome | H21: =IF(E21="","",IF(E21=G21,"Yes","No")) -> Yes | I21: Wikipedia
A22: BB28 | B22: Week 2 | D22: Yash | E22: Rome | G22: Rome | H22: =IF(E22="","",IF(E22=G22,"Yes","No")) -> Yes | I22: Wikipedia
A23: BB28 | B23: Week 2 | D23: Barrett | E23: Rome | G23: Rome | H23: =IF(E23="","",IF(E23=G23,"Yes","No")) -> Yes | I23: Wikipedia
A24: BB28 | B24: Week 2 | D24: Angela | E24: Rome | G24: Rome | H24: =IF(E24="","",IF(E24=G24,"Yes","No")) -> Yes | I24: Wikipedia
A25: BB28 | B25: Week 2 | D25: La Trice | E25: Rome | G25: Rome | H25: =IF(E25="","",IF(E25=G25,"Yes","No")) -> Yes | I25: Wikipedia
A26: BB28 | B26: Week 2 | D26: Haley | E26: Rome | G26: Rome | H26: =IF(E26="","",IF(E26=G26,"Yes","No")) -> Yes | I26: Wikipedia
A27: BB28 | B27: Week 2 | D27: Mallory | E27: Rome | G27: Rome | H27: =IF(E27="","",IF(E27=G27,"Yes","No")) -> Yes | I27: Wikipedia
A28: BB28 | B28: Week 2 | D28: Kamu | E28: Rome | G28: Rome | H28: =IF(E28="","",IF(E28=G28,"Yes","No")) -> Yes | I28: Wikipedia
A29: BB28 | B29: Week 2 | D29: Chuk | E29: Rome | G29: Rome | H29: =IF(E29="","",IF(E29=G29,"Yes","No")) -> Yes | I29: Wikipedia
A30: BB28 | B30: Week 2 | D30: Lyric | E30: Rome | G30: Rome | H30: =IF(E30="","",IF(E30=G30,"Yes","No")) -> Yes | I30: Wikipedia
A31: BB28 | B31: Week 2 | D31: Jason | E31: Rome | G31: Rome | H31: =IF(E31="","",IF(E31=G31,"Yes","No")) -> Yes | I31: Wikipedia
A32: BB28 | B32: Week 2 | D32: Devens | F32: Head of Household | G32: Rome | H32: =IF(E32="","",IF(E32=G32,"Yes","No")) | I32: Wikipedia
A33: BB28 | B33: Week 2 | D33: Melody | F33: Nominated | G33: Rome | H33: =IF(E33="","",IF(E33=G33,"Yes","No")) | I33: Wikipedia
A34: BB28 | B34: Week 2 | D34: Rome | F34: Nominated | G34: Rome | H34: =IF(E34="","",IF(E34=G34,"Yes","No")) | I34: Wikipedia
A35: BB28 | B35: Week 3 | D35: Devens | E35: Jason | G35: Jason | H35: =IF(E35="","",IF(E35=G35,"Yes","No")) -> Yes | I35: Wikipedia
A36: BB28 | B36: Week 3 | D36: Taylor | E36: Jason | G36: Jason | H36: =IF(E36="","",IF(E36=G36,"Yes","No")) -> Yes | I36: Wikipedia
A37: BB28 | B37: Week 3 | D37: Drew | E37: Jason | G37: Jason | H37: =IF(E37="","",IF(E37=G37,"Yes","No")) -> Yes | I37: Wikipedia
A38: BB28 | B38: Week 3 | D38: Dee | E38: Jason | G38: Jason | H38: =IF(E38="","",IF(E38=G38,"Yes","No")) -> Yes | I38: Wikipedia
A39: BB28 | B39: Week 3 | D39: Melody | E39: Jason | G39: Jason | H39: =IF(E39="","",IF(E39=G39,"Yes","No")) -> Yes | I39: Wikipedia
A40: BB28 | B40: Week 3 | D40: Yash | E40: Jason | G40: Jason | H40: =IF(E40="","",IF(E40=G40,"Yes","No")) -> Yes | I40: Wikipedia
A41: BB28 | B41: Week 3 | D41: Barrett | E41: Jason | G41: Jason | H41: =IF(E41="","",IF(E41=G41,"Yes","No")) -> Yes | I41: Wikipedia
...

Sheet Players
A1: Season | B1: Player | C1: Result | D1: HOHs | E1: Vetoes | F1: Twist wins | G1: Noms | H1: Final noms | I1: Votes against | J1: Votes cast | K1: With the house | L1: Source | M1: Looks right? | N1: Correction
A2: BB28 | B2: Devens | C2: Winner | D2: =COUNTIFS(Weeks!$A$2:$A$115,$A2,Weeks!$S$2:$S$115,"*;"&$B2&";*") -> 2 | E2: =COUNTIFS(Weeks!$A$2:$A$115,$A2,Weeks!$T$2:$T$115,"*;"&$B2&";*") -> 3 | F2: =COUNTIFS(Weeks!$A$2:$A$115,$A2,Weeks!$W$2:$W$115,"*;"&$B2&";*") -> 2 | G2: =COUNTIFS(Weeks!$A$2:$A$115,$A2,Weeks!$U$2:$U$115,"*;"&$B2&";*") -> 2 | H2: =COUNTIFS(Weeks!$A$2:$A$115,$A2,Weeks!$V$2:$V$115,"*;"&$B2&";*") -> 1 | I2: =COUNTIFS(Votes!$A$2:$A$1113,$A2,Votes!$E$2:$E$1113,$B2) -> 0 | J2: =COUNTIFS(Votes!$A$2:$A$1113,$A2,Votes!$D$2:$D$1113,$B2,Votes!$E$2:$E$1113,"<>") -> 11 | K2: =COUNTIFS(Votes!$A$2:$A$1113,$A2,Votes!$D$2:$D$1113,$B2,Votes!$H$2:$H$1113,"Yes") -> 11 | L2: Wikipedia
A3: BB28 | B3: Taylor | C3: Runner-up | D3: =COUNTIFS(Weeks!$A$2:$A$115,$A3,Weeks!$S$2:$S$115,"*;"&$B3&";*") -> 1 | E3: =COUNTIFS(Weeks!$A$2:$A$115,$A3,Weeks!$T$2:$T$115,"*;"&$B3&";*") -> 1 | F3: =COUNTIFS(Weeks!$A$2:$A$115,$A3,Weeks!$W$2:$W$115,"*;"&$B3&";*") -> 0 | G3: =COUNTIFS(Weeks!$A$2:$A$115,$A3,Weeks!$U$2:$U$115,"*;"&$B3&";*") -> 4 | H3: =COUNTIFS(Weeks!$A$2:$A$115,$A3,Weeks!$V$2:$V$115,"*;"&$B3&";*") -> 5 | I3: =COUNTIFS(Votes!$A$2:$A$1113,$A3,Votes!$E$2:$E$1113,$B3) -> 6 | J3: =COUNTIFS(Votes!$A$2:$A$1113,$A3,Votes!$D$2:$D$1113,$B3,Votes!$E$2:$E$1113,"<>") -> 7 | K3: =COUNTIFS(Votes!$A$2:$A$1113,$A3,Votes!$D$2:$D$1113,$B3,Votes!$H$2:$H$1113,"Yes") -> 5 | L3: Wikipedia
A4: BB28 | B4: Drew | C4: Evicted (Day 87) | D4: =COUNTIFS(Weeks!$A$2:$A$115,$A4,Weeks!$S$2:$S$115,"*;"&$B4&";*") -> 1 | E4: =COUNTIFS(Weeks!$A$2:$A$115,$A4,Weeks!$T$2:$T$115,"*;"&$B4&";*") -> 3 | F4: =COUNTIFS(Weeks!$A$2:$A$115,$A4,Weeks!$W$2:$W$115,"*;"&$B4&";*") -> 2 | G4: =COUNTIFS(Weeks!$A$2:$A$115,$A4,Weeks!$U$2:$U$115,"*;"&$B4&";*") -> 5 | H4: =COUNTIFS(Weeks!$A$2:$A$115,$A4,Weeks!$V$2:$V$115,"*;"&$B4&";*") -> 0 | I4: =COUNTIFS(Votes!$A$2:$A$1113,$A4,Votes!$E$2:$E$1113,$B4) -> 0 | J4: =COUNTIFS(Votes!$A$2:$A$1113,$A4,Votes!$D$2:$D$1113,$B4,Votes!$E$2:$E$1113,"<>") -> 12 | K4: =COUNTIFS(Votes!$A$2:$A$1113,$A4,Votes!$D$2:$D$1113,$B4,Votes!$H$2:$H$1113,"Yes") -> 10 | L4: Wikipedia
A5: BB28 | B5: Dee | C5: Evicted (Day 80) | D5: =COUNTIFS(Weeks!$A$2:$A$115,$A5,Weeks!$S$2:$S$115,"*;"&$B5&";*") -> 2 | E5: =COUNTIFS(Weeks!$A$2:$A$115,$A5,Weeks!$T$2:$T$115,"*;"&$B5&";*") -> 0 | F5: =COUNTIFS(Weeks!$A$2:$A$115,$A5,Weeks!$W$2:$W$115,"*;"&$B5&";*") -> 0 | G5: =COUNTIFS(Weeks!$A$2:$A$115,$A5,Weeks!$U$2:$U$115,"*;"&$B5&";*") -> 4 | H5: =COUNTIFS(Weeks!$A$2:$A$115,$A5,Weeks!$V$2:$V$115,"*;"&$B5&";*") -> 3 | I5: =COUNTIFS(Votes!$A$2:$A$1113,$A5,Votes!$E$2:$E$1113,$B5) -> 4 | J5: =COUNTIFS(Votes!$A$2:$A$1113,$A5,Votes!$D$2:$D$1113,$B5,Votes!$E$2:$E$1113,"<>") -> 8 | K5: =COUNTIFS(Votes!$A$2:$A$1113,$A5,Votes!$D$2:$D$1113,$B5,Votes!$H$2:$H$1113,"Yes") -> 8 | L5: Wikipedia
A6: BB28 | B6: Melody | C6: Evicted (Day 77) | D6: =COUNTIFS(Weeks!$A$2:$A$115,$A6,Weeks!$S$2:$S$115,"*;"&$B6&";*") -> 1 | E6: =COUNTIFS(Weeks!$A$2:$A$115,$A6,Weeks!$T$2:$T$115,"*;"&$B6&";*") -> 0 | F6: =COUNTIFS(Weeks!$A$2:$A$115,$A6,Weeks!$W$2:$W$115,"*;"&$B6&";*") -> 1 | G6: =COUNTIFS(Weeks!$A$2:$A$115,$A6,Weeks!$U$2:$U$115,"*;"&$B6&";*") -> 4 | H6: =COUNTIFS(Weeks!$A$2:$A$115,$A6,Weeks!$V$2:$V$115,"*;"&$B6&";*") -> 3 | I6: =COUNTIFS(Votes!$A$2:$A$1113,$A6,Votes!$E$2:$E$1113,$B6) -> 6 | J6: =COUNTIFS(Votes!$A$2:$A$1113,$A6,Votes!$D$2:$D$1113,$B6,Votes!$E$2:$E$1113,"<>") -> 8 | K6: =COUNTIFS(Votes!$A$2:$A$1113,$A6,Votes!$D$2:$D$1113,$B6,Votes!$H$2:$H$1113,"Yes") -> 4 | L6: Wikipedia
A7: BB28 | B7: Yash | C7: Evicted (Day 73) | D7: =COUNTIFS(Weeks!$A$2:$A$115,$A7,Weeks!$S$2:$S$115,"*;"&$B7&";*") -> 2 | E7: =COUNTIFS(Weeks!$A$2:$A$115,$A7,Weeks!$T$2:$T$115,"*;"&$B7&";*") -> 3 | F7: =COUNTIFS(Weeks!$A$2:$A$115,$A7,Weeks!$W$2:$W$115,"*;"&$B7&";*") -> 1 | G7: =COUNTIFS(Weeks!$A$2:$A$115,$A7,Weeks!$U$2:$U$115,"*;"&$B7&";*") -> 2 | H7: =COUNTIFS(Weeks!$A$2:$A$115,$A7,Weeks!$V$2:$V$115,"*;"&$B7&";*") -> 1 | I7: =COUNTIFS(Votes!$A$2:$A$1113,$A7,Votes!$E$2:$E$1113,$B7) -> 2 | J7: =COUNTIFS(Votes!$A$2:$A$1113,$A7,Votes!$D$2:$D$1113,$B7,Votes!$E$2:$E$1113,"<>") -> 8 | K7: =COUNTIFS(Votes!$A$2:$A$1113,$A7,Votes!$D$2:$D$1113,$B7,Votes!$H$2:$H$1113,"Yes") -> 7 | L7: Wikipedia
A8: BB28 | B8: Barrett | C8: Evicted (Day 73) | D8: =COUNTIFS(Weeks!$A$2:$A$115,$A8,Weeks!$S$2:$S$115,"*;"&$B8&";*") -> 1 | E8: =COUNTIFS(Weeks!$A$2:$A$115,$A8,Weeks!$T$2:$T$115,"*;"&$B8&";*") -> 0 | F8: =COUNTIFS(Weeks!$A$2:$A$115,$A8,Weeks!$W$2:$W$115,"*;"&$B8&";*") -> 0 | G8: =COUNTIFS(Weeks!$A$2:$A$115,$A8,Weeks!$U$2:$U$115,"*;"&$B8&";*") -> 2 | H8: =COUNTIFS(Weeks!$A$2:$A$115,$A8,Weeks!$V$2:$V$115,"*;"&$B8&";*") -> 2 | I8: =COUNTIFS(Votes!$A$2:$A$1113,$A8,Votes!$E$2:$E$1113,$B8) -> 4 | J8: =COUNTIFS(Votes!$A$2:$A$1113,$A8,Votes!$D$2:$D$1113,$B8,Votes!$E$2:$E$1113,"<>") -> 7 | K8: =COUNTIFS(Votes!$A$2:$A$1113,$A8,Votes!$D$2:$D$1113,$B8,Votes!$H$2:$H$1113,"Yes") -> 6 | L8: Wikipedia
A9: BB28 | B9: Angela | C9: Evicted (Day 66) | D9: =COUNTIFS(Weeks!$A$2:$A$115,$A9,Weeks!$S$2:$S$115,"*;"&$B9&";*") -> 0 | E9: =COUNTIFS(Weeks!$A$2:$A$115,$A9,Weeks!$T$2:$T$115,"*;"&$B9&";*") -> 0 | F9: =COUNTIFS(Weeks!$A$2:$A$115,$A9,Weeks!$W$2:$W$115,"*;"&$B9&";*") -> 1 | G9: =COUNTIFS(Weeks!$A$2:$A$115,$A9,Weeks!$U$2:$U$115,"*;"&$B9&";*") -> 2 | H9: =COUNTIFS(Weeks!$A$2:$A$115,$A9,Weeks!$V$2:$V$115,"*;"&$B9&";*") -> 1 | I9: =COUNTIFS(Votes!$A$2:$A$1113,$A9,Votes!$E$2:$E$1113,$B9) -> 3 | J9: =COUNTIFS(Votes!$A$2:$A$1113,$A9,Votes!$D$2:$D$1113,$B9,Votes!$E$2:$E$1113,"<>") -> 8 | K9: =COUNTIFS(Votes!$A$2:$A$1113,$A9,Votes!$D$2:$D$1113,$B9,Votes!$H$2:$H$1113,"Yes") -> 7 | L9: Wikipedia
A10: BB28 | B10: La Trice | C10: Evicted (Day 59) | D10: =COUNTIFS(Weeks!$A$2:$A$115,$A10,Weeks!$S$2:$S$115,"*;"&$B10&";*") -> 1 | E10: =COUNTIFS(Weeks!$A$2:$A$115,$A10,Weeks!$T$2:$T$115,"*;"&$B10&";*") -> 1 | F10: =COUNTIFS(Weeks!$A$2:$A$115,$A10,Weeks!$W$2:$W$115,"*;"&$B10&";*") -> 0 | G10: =COUNTIFS(Weeks!$A$2:$A$115,$A10,Weeks!$U$2:$U$115,"*;"&$B10&";*") -> 3 | H10: =COUNTIFS(Weeks!$A$2:$A$115,$A10,Weeks!$V$2:$V$115,"*;"&$B10&";*") -> 2 | I10: =COUNTIFS(Votes!$A$2:$A$1113,$A10,Votes!$E$2:$E$1113,$B10) -> 4 | J10: =COUNTIFS(Votes!$A$2:$A$1113,$A10,Votes!$D$2:$D$1113,$B10,Votes!$E$2:$E$1113,"<>") -> 5 | K10: =COUNTIFS(Votes!$A$2:$A$1113,$A10,Votes!$D$2:$D$1113,$B10,Votes!$H$2:$H$1113,"Yes") -> 4 | L10: Wikipedia
A11: BB28 | B11: Haley | C11: Eliminated (Day 53) | D11: =COUNTIFS(Weeks!$A$2:$A$115,$A11,Weeks!$S$2:$S$115,"*;"&$B11&";*") -> 1 | E11: =COUNTIFS(Weeks!$A$2:$A$115,$A11,Weeks!$T$2:$T$115,"*;"&$B11&";*") -> 0 | F11: =COUNTIFS(Weeks!$A$2:$A$115,$A11,Weeks!$W$2:$W$115,"*;"&$B11&";*") -> 1 | G11: =COUNTIFS(Weeks!$A$2:$A$115,$A11,Weeks!$U$2:$U$115,"*;"&$B11&";*") -> 2 | H11: =COUNTIFS(Weeks!$A$2:$A$115,$A11,Weeks!$V$2:$V$115,"*;"&$B11&";*") -> 1 | I11: =COUNTIFS(Votes!$A$2:$A$1113,$A11,Votes!$E$2:$E$1113,$B11) -> 1 | J11: =COUNTIFS(Votes!$A$2:$A$1113,$A11,Votes!$D$2:$D$1113,$B11,Votes!$E$2:$E$1113,"<>") -> 5 | K11: =COUNTIFS(Votes!$A$2:$A$1113,$A11,Votes!$D$2:$D$1113,$B11,Votes!$H$2:$H$1113,"Yes") -> 4 | L11: Wikipedia
A12: BB28 | B12: Mallory | C12: Evicted (Day 52) | D12: =COUNTIFS(Weeks!$A$2:$A$115,$A12,Weeks!$S$2:$S$115,"*;"&$B12&";*") -> 0 | E12: =COUNTIFS(Weeks!$A$2:$A$115,$A12,Weeks!$T$2:$T$115,"*;"&$B12&";*") -> 1 | F12: =COUNTIFS(Weeks!$A$2:$A$115,$A12,Weeks!$W$2:$W$115,"*;"&$B12&";*") -> 1 | G12: =COUNTIFS(Weeks!$A$2:$A$115,$A12,Weeks!$U$2:$U$115,"*;"&$B12&";*") -> 2 | H12: =COUNTIFS(Weeks!$A$2:$A$115,$A12,Weeks!$V$2:$V$115,"*;"&$B12&";*") -> 1 | I12: =COUNTIFS(Votes!$A$2:$A$1113,$A12,Votes!$E$2:$E$1113,$B12) -> 6 | J12: =COUNTIFS(Votes!$A$2:$A$1113,$A12,Votes!$D$2:$D$1113,$B12,Votes!$E$2:$E$1113,"<>") -> 6 | K12: =COUNTIFS(Votes!$A$2:$A$1113,$A12,Votes!$D$2:$D$1113,$B12,Votes!$H$2:$H$1113,"Yes") -> 6 | L12: Wikipedia
A13: BB28 | B13: Kamu | C13: Evicted (Day 45) | D13: =COUNTIFS(Weeks!$A$2:$A$115,$A13,Weeks!$S$2:$S$115,"*;"&$B13&";*") -> 1 | E13: =COUNTIFS(Weeks!$A$2:$A$115,$A13,Weeks!$T$2:$T$115,"*;"&$B13&";*") -> 1 | F13: =COUNTIFS(Weeks!$A$2:$A$115,$A13,Weeks!$W$2:$W$115,"*;"&$B13&";*") -> 0 | G13: =COUNTIFS(Weeks!$A$2:$A$115,$A13,Weeks!$U$2:$U$115,"*;"&$B13&";*") -> 0 | H13: =COUNTIFS(Weeks!$A$2:$A$115,$A13,Weeks!$V$2:$V$115,"*;"&$B13&";*") -> 1 | I13: =COUNTIFS(Votes!$A$2:$A$1113,$A13,Votes!$E$2:$E$1113,$B13) -> 8 | J13: =COUNTIFS(Votes!$A$2:$A$1113,$A13,Votes!$D$2:$D$1113,$B13,Votes!$E$2:$E$1113,"<>") -> 4 | K13: =COUNTIFS(Votes!$A$2:$A$1113,$A13,Votes!$D$2:$D$1113,$B13,Votes!$H$2:$H$1113,"Yes") -> 3 | L13: Wikipedia
... A132: BB21 | B132: David | C132: Remained evicted (Day 30) | D132: =COUNTIFS(Weeks!$A$2:$A$115,$A132,Weeks!$S$2:$S$115,"*;"&$B132&";*") -> 0 | E132: =COUNTIFS(Weeks!$A$2:$A$115,$A132,Weeks!$T$2:$T$115,"*;"&$B132&";*") -> 0 | F132: =COUNTIFS(Weeks!$A$2:$A$115,$A132,Weeks!$W$2:$W$115,"*;"&$B132&";*") -> 0 | G132: =COUNTIFS(Weeks!$A$2:$A$115,$A132,Weeks!$U$2:$U$115,"*;"&$B132&";*") -> 0 | H132: =COUNTIFS(Weeks!$A$2:$A$115,$A132,Weeks!$V$2:$V$115,"*;"&$B132&";*") -> 0 | I132: =COUNTIFS(Votes!$A$2:$A$1113,$A132,Votes!$E$2:$E$1113,$B132) -> 0 | J132: =COUNTIFS(Votes!$A$2:$A$1113,$A132,Votes!$D$2:$D$1113,$B132,Votes!$E$2:$E$1113,"<>") -> 0 | K132: =COUNTIFS(Votes!$A$2:$A$1113,$A132,Votes!$D$2:$D$1113,$B132,Votes!$H$2:$H$1113,"Yes") -> 0 | L132: Wikipedia

Sheet Competitions
A1: Season | B1: Week | C1: Kind | D1: Competition | E1: Won by | F1: Round | G1: From the summary | H1: Source | I1: Looks right? | J1: Correction
A2: BB28 | B2: Week 1 | C2: Veto | D2: Back From the Future | E2: (not tied to a winner) | G2: In the Power of Veto Competition ("Back From the Future"), each HouseGuest must help future Howie Gordon defeat future Will Kirby by constructing a path between the "Table Time Machine" and Will's throne using a series of tubes. | H2: Wikipedia
A3: BB28 | B3: Week 2 | C3: HOH | D3: Achy Breaky HOH | E3: (not tied to a winner) | G3: In the Head of Household Competition ("Achy Breaky HOH"), HouseGuests must slide a disk down a table, attempting to land it on the highest-scoring numbered spots. | H3: Wikipedia
A4: BB28 | B4: Week 2 | C4: Veto | D4: Flower Power | E4: (not tied to a winner) | G4: In the Power of Veto Competition ("Flower Power"), HouseGuests must find and retrieve twelve hidden puzzle pieces. | H4: Wikipedia
A5: BB28 | B5: Week 3 | C5: HOH | D5: Wrestlegasm | E5: (not tied to a winner) | G5: The episode concluded with the HouseGuests beginning the third Head of Household competition, "Wrestlegasm". | H5: Wikipedia
A6: BB28 | B6: Week 3 | C6: Veto | D6: The Pickle Ball | E6: (not tied to a winner) | G6: In the Power of Veto Competition ("The Pickle Ball"), each HouseGuest must go head-to-head against another competitor. | H6: Wikipedia
A7: BB28 | B7: Week 4 | C7: HOH | D7: Jack The Ripper | E7: Haley | F7: 1 | G7: In the Head of Household competition ("Jack The Ripper"), HouseGuests are given five minutes to study six rooms before answering questions about the items they observed. | H7: Wikipedia
A8: BB28 | B8: Week 5 | C8: HOH | D8: Sasquatch Watch | E8: La Trice | F8: 1 | G8: In the Head of Household Competition ("Sasquatch Watch"), HouseGuest must hang on a tilting wall while being doused in water and slime. | H8: Wikipedia
A9: BB28 | B9: Week 5 | C9: Veto | D9: Saturday Night Veto | E9: (not tied to a winner) | G9: In the Veto Competition ("Saturday Night Veto"), HouseGuests must cross a bridge by stepping on one of two tiles that would highlight red or green. | H9: Wikipedia
A10: BB28 | B10: Week 6 | C10: HOH | D10: Bugs in the System | E10: (not tied to a winner) | G10: In the Head of Household competition ("Bugs in the System"), the HouseGuests face off head-to-head. | H10: Wikipedia
A11: BB28 | B11: Week 6 | C11: Veto | D11: OTEV the Belligerent B-Movie Slob | E11: (not tied to a winner) | G11: In the Veto Competition ("OTEV the Belligerent B-Movie Slob"), players must find and return the correct HouseGuest's name based on OTEV’s clues. | H11: Wikipedia
A12: BB28 | B12: Week 7 | C12: Veto | D12: Feel The Burn | E12: (not tied to a winner) | G12: They fear that "F.A.P." would take advantage of having the majority within the "Mosh Pit." In the Veto Competition ("Feel The Burn"), players must use various exercise machines to complete the most reps within a set time limit. | H12: Wikipedia
A13: BB28 | B13: Week 8 | C13: HOH | D13: 2026: A Zing Odyssey | E13: (not tied to a winner) | G13: In the Head of Household Competition ("2026: A Zing Odyssey"), the HouseGuests must answer a series of true-or-false questions, earning one point for each correct answer. | H13: Wikipedia
A14: BB28 | B14: Week 8 | C14: Veto | D14: The Gold, the Bad, and the Ugly | E14: Yash | F14: 1 | G14: In the Veto Competition ("The Gold, the Bad, and the Ugly"), the players must balance and transfer 25 gold nuggets using a seesaw shovel. | H14: Wikipedia
A15: BB28 | B15: Week 9 | C15: HOH | D15: Rainbow Rollers | E15: (not tied to a winner) | G15: The episode concluded with the HouseGuests beginning the ninth Head of Household competition, "Rainbow Rollers". | H15: Wikipedia
A16: BB28 | B16: Week 9 | C16: Veto | D16: BB Comics | E16: Yash | F16: 1 | G16: In the Veto Competition ("BB Comics"), players must zipline past a wall of superhero-themed comics, memorize their order, spot the differences, and recreate the correct sequence on their boards. | H16: Wikipedia
A17: BB28 | B17: Week 10 | C17: HOH | D17: Wet and Wild West | E17: (not tied to a winner) | G17: In the Head of Household Competition ("Wet and Wild West""), HouseGuests must catch water, fill a jar and retrieve at apple. | H17: Wikipedia
A18: BB28 | B18: Week 10 | C18: Veto | D18: Circle of Trust | E18: (not tied to a winner) | G18: In the Veto Competition ("Circle of Trust"), HouseGuests must stand on a spot whilst holding up a lie detector with their sword, with the last person standing winning the veto. | H18: Wikipedia
A19: BB28 | B19: Week 10 | C19: HOH | D19: Bleeping Through Time | E19: (not tied to a winner) | G19: Following Barrett’s eviction, Julie announces that it is double eviction, and the HouseGuests participate in the Head of Household Competition, ("Bleeping Through Time"). | H19: Wikipedia
A20: BB28 | B20: Week 10 | C20: Veto | D20: Great Ball of China | E20: Drew | F20: 1 | G20: In the Veto Competition ("Great Ball of China"), HouseGuests must first construct a wall puzzle and then roll a ball along it into a bin. | H20: Wikipedia
A21: BB28 | B21: Week 11 | C21: HOH | D21: Reverse the Curse | E21: Devens | F21: 1 | G21: In the Head of Household competition ("Reverse the Curse"), the HouseGuests must use tweezers to complete a miniature picture puzzle. | H21: Wikipedia
A22: BB28 | B22: Week 11 | C22: Veto | D22: Block Like an Egyptian | E22: (not tied to a winner) | G22: In the Veto Competition ("Block Like an Egyptian"), the players must traverse a booby-trapped course to deliver a mummified corpse to its coffin. | H22: Wikipedia
A23: BB28 | B23: Week 11 | C23: HOH | D23: Eternally Yours | E23: (not tied to a winner) | G23: In the Head of Household Competition ("Eternally Yours"), HouseGuests must correctly identify the missing player from a series of images before assembling a puzzle. | H23: Wikipedia
A24: BB28 | B24: Week 11 | C24: Veto | D24: Time Travel Toilet | E24: (not tied to a winner) | G24: In the Veto Competition ("Time Travel Toilet"), players must correctly identify the day displayed on the screen. | H24: Wikipedia
A25: BB28 | B25: Week 12 | C25: HOH | D25: To Be HoH or Not to Be | E25: (not tied to a winner) | G25: In Part 2 of the HoH competition, "To Be HoH or Not to Be", HouseGuests must correctly match the evicted players by knocking down their cutouts with a slingshot. | H25: Wikipedia
A26: BB27 | B26: Week 1 | C26: Veto | D26: Campsite Caper | E26: Ashley | F26: 1 | G26: Rachel and Zach are selected to join Amy, Ashley, Vince, and Zae in the "Campsite Caper" Veto competition. | H26: Wikipedia
A27: BB27 | B27: Week 3 | C27: HOH | D27: Twin Witness News | E27: Lauren | F27: 1 | G27: In the “Twin Witness News” Head of Household competition, HouseGuests must correctly answer a series of true-or-false questions based on events witnessed by former Big Brother 17 HouseGuests, Julia and Liz Nolan. | H27: Wikipedia
A28: BB27 | B28: Week 3 | C28: Veto | D28: Basement Break In | E28: Keanu | F28: 1 | G28: In the "Basement Break In" Power of Veto competition, players must retrieve a crystal through a laser maze in the shortest amount of time. | H28: Wikipedia
A29: BB27 | B29: Week 4 | C29: HOH | D29: Killer Carnival | E29: (not tied to a winner) | G29: In the three-round “Killer Carnival” Head of Household competition, HouseGuests begin in teams of four. | H29: Wikipedia
A30: BB27 | B30: Week 4 | C30: Veto | D30: Flee the Scene | E30: (not tied to a winner) | G30: In the "Flee the Scene" veto competition, HouseGuests must cross a bridge by stepping on one of two tiles that would highlight red or green. | H30: Wikipedia
A31: BB27 | B31: Week 5 | C31: HOH | D31: Jack the Dipper | E31: (not tied to a winner) | G31: In the "Jack the Dipper" Head of Household competition, HouseGuests face off head-to-head. | H31: Wikipedia
A32: BB27 | B32: Week 5 | C32: Veto | D32: Elusive Target | E32: (not tied to a winner) | G32: In the "Elusive Target" Veto competition, HouseGuests must slide a disk, aiming not to score the lowest each round. | H32: Wikipedia
A33: BB27 | B33: Week 6 | C33: HOH | D33: Party Slasher | E33: Rachel | F33: 1 | G33: In the “Party Slasher” Head of Household competition, HouseGuests are given five minutes to study six rooms before answering questions about the items they observed. | H33: Wikipedia
A34: BB27 | B34: Week 7 | C34: HOH | D34: Mystère Express | E34: (not tied to a winner) | G34: In the “Mystère Express” Head of Household competition, players hang on a tilting wall while being doused in water and slime. | H34: Wikipedia
A35: BB27 | B35: Week 7 | C35: Veto | D35: Wine to Die For | E35: (not tied to a winner) | G35: In the Veto competition, "Wine to Die For", players must randomly present two glasses of wine, one poisoned and one safe, to a chosen target, who must then guess which glass is safe. | H35: Wikipedia
A36: BB27 | B36: Week 8 | C36: HOH | D36: Mystère Moments | E36: Keanu | F36: 1 | G36: In the "Mystère Moments" HoH competition, players are tested with a series of True or False questions based on the video clips. | H36: Wikipedia
A37: BB27 | B37: Week 8 | C37: Veto | D37: Charcuterie Protection Agency | E37: Morgan | F37: 1 | G37: In the “Charcuterie Protection Agency” Power of Veto competition, hosted by Big Brother 26 contestant Angela Murray, players race to stack 35 variously sized charcuterie pieces in the fastest time. | H37: Wikipedia
A38: BB27 | B38: Week 9 | C38: Veto | D38: BB Comics | E38: Morgan | F38: 1 | G38: In the "BB Comics" veto competition, players must zipline past a wall of superhero-themed comics, memorize the order, and recreate the correct sequence on their boards. | H38: Wikipedia
A39: BB27 | B39: Week 10 | C39: HOH | D39: The Last Zing | E39: Vince | F39: 1 | G39: In the Head of Household competition, "The Last Zing", players must answer a series of true-or-false questions. | H39: Wikipedia
A40: BB27 | B40: Week 10 | C40: Veto | D40: BB CSI | E40: Morgan | F40: 1 | G40: In the "BB CSI" Veto competition, players must balance and transfer 25 pieces of evidence onto the lens of a giant magnifying glass. | H40: Wikipedia
...

Sheet BB Wiki comps
A1: Season | B1: Week | C1: Day | D1: Type | E1: Competition | F1: Format | G1: Category | H1: Result | I1: Round | J1: Source | K1: Looks right? | L1: Correction
A2: BB28 | B2: Week 1 | C2: 1 | D2: Immunity | E2: Find the BB-tonium | F2: Reclaim the Relic | H2: Ashley & Barrett fail to advance | J2: BB Wiki
A3: BB28 | B3: Week 1 | C3: 1 | D3: Immunity | E3: 1988 Long Beach, CA | F3: In The Balance | H3: Rome wins Safety | J3: BB Wiki
A4: BB28 | B4: Week 1 | C4: 1 | D4: Immunity | E4: 2018 Fiji | F4: Build the Bridge | H4: Chuk wins Safety | J4: BB Wiki
A5: BB28 | B5: Week 1 | C5: 1 | D5: Immunity | E5: 2010 Las Vegas, NV | F5: Sequence Explosion | H5: Jason wins Safety | J5: BB Wiki
A6: BB28 | B6: Week 1 | C6: 1 | D6: HOH | E6: 175 Million BC | F6: Pyramid | G6: Endurance | H6: Dee wins HOH | I6: 1 | J6: BB Wiki
A7: BB28 | B7: Week 1 | C7: 5 | D7: POV | E7: Back From the Future | F7: Pipeline | G7: Puzzle | H7: Mallory wins the Veto | I7: 1 | J7: BB Wiki
A8: BB28 | B8: Week 1 | C8: 10 | D8: Block Buster | E8: Do Over | F8: Living Art | H8: Yash is saved | J8: BB Wiki
A9: BB28 | B9: Week 2 | C9: 10 | D9: HOH | E9: Achy Breaky HOH | F9: Shootout | G9: Skill | H9: Devens wins HOH | I9: 1 | J9: BB Wiki
A10: BB28 | B10: Week 2 | C10: 11 | D10: Time Capsule | H10: Angela is punished | J10: BB Wiki
A11: BB28 | B11: Week 2 | C11: 12 | D11: POV | E11: Flower Power | F11: Fitting In | G11: Puzzle | H11: Devens wins the Veto | I11: 1 | J11: BB Wiki
A12: BB28 | B12: Week 2 | C12: 17 | D12: Block Buster | E12: Pirate's Booty | F12: Tower of Hanoi | H12: Jason is saved | J12: BB Wiki
A13: BB28 | B13: Week 3 | C13: 17 | D13: HOH | E13: Wrestlegasm 85 | F13: What Did They Just Do? | G13: Mental | H13: Kamu wins HOH | I13: 1 | J13: BB Wiki
A14: BB28 | B14: Week 3 | C14: 18 | D14: Time Capsule | H14: Devens is rewarded | J14: BB Wiki
A15: BB28 | B15: Week 3 | C15: 19 | D15: POV | E15: The Pickle Ball | F15: Bowlerina | G15: Skill | H15: Lyric wins the Veto | I15: 1 | J15: BB Wiki
A16: BB28 | B16: Week 3 | C16: 24 | D16: Block Buster | E16: Video Tape Tumble | H16: Mallory is saved | J16: BB Wiki
A17: BB28 | B17: Week 4 | C17: 24 | D17: HOH | E17: Jack the Ripper | F17: Hide and Seek | G17: Mental | H17: Haley wins HOH | I17: 1 | J17: BB Wiki
A18: BB28 | B18: Week 4 | C18: 25 | D18: Time Capsule | H18: Dee is rewarded | J18: BB Wiki
A19: BB28 | B19: Week 4 | C19: 26 | D19: POV | E19: Murder at the Masquerade | F19: To Drink or to Bluff | G19: Crapshoot | H19: Taylor wins the Veto | I19: 1 | J19: BB Wiki
A20: BB28 | B20: Week 4 | C20: 31 | D20: Block Buster | E20: The Paw Patrol Dino Puzzle | F20: Fitting In | H20: Drew is saved | J20: BB Wiki
A21: BB28 | B21: Week 5 | C21: 31 | D21: HOH | E21: Sasquatch Watch | F21: The Wall | G21: Endurance | H21: La Trice wins HOH | I21: 1 | J21: BB Wiki
A22: BB28 | B22: Week 5 | C22: 32 | D22: Time Capsule | H22: Mallory is punished | J22: BB Wiki
A23: BB28 | B23: Week 5 | C23: 33 | D23: POV | E23: Saturday Night Veto | F23: Binary Bridge | G23: Crapshoot | H23: Kamu wins the Veto | I23: 1 | J23: BB Wiki
A24: BB28 | B24: Week 5 | C24: 38 | D24: Block Buster | E24: Newton's Apples | F24: Carnival Quick Shot | H24: Haley is saved | J24: BB Wiki
A25: BB28 | B25: Week 6 | C25: 38 | D25: HOH | E25: Bugs in the System | F25: Knockout | G25: Mental | H25: Yash wins HOH | I25: 1 | J25: BB Wiki
A26: BB28 | B26: Week 6 | C26: 39 | D26: Time Capsule | H26: Melody is punished | J26: BB Wiki
A27: BB28 | B27: Week 6 | C27: 40 | D27: POV | E27: OTEV the Belligerent B-Movie Blob | F27: OTEV | G27: Hybrid | H27: Yash wins the Veto | I27: 1 | J27: BB Wiki
A28: BB28 | B28: Week 6 | C28: 45 | D28: Block Buster | E28: Space Race | F28: Niagara Balls | H28: Angela is saved | J28: BB Wiki
A29: BB28 | B29: Week 7 | C29: 45 | D29: HOH | E29: Norse By Norsewest | F29: Only One Path | G29: Physical | H29: Dee wins HOH | I29: 1 | J29: BB Wiki
A30: BB28 | B30: Week 7 | C30: 46 | D30: Time Capsule | H30: Drew is rewarded | J30: BB Wiki
A31: BB28 | B31: Week 7 | C31: 47 | D31: POV | E31: Feel The Burn | G31: Physical | H31: La Trice wins the Veto | I31: 1 | J31: BB Wiki
A32: BB28 | B32: Week 7 | C32: 52 | D32: Block Buster | E32: BB Grand Cliptacular | F32: Getting Loopy | H32: Drew is saved | J32: BB Wiki
A33: BB28 | B33: Week 8 | C33: 52-53 | D33: Immunity | E33: Stones of Safety | F33: In The Balance | H33: Dee wins Safety | J33: BB Wiki
A34: BB28 | B34: Week 8 | C34: 52-53 | D34: Hit The Road | E34: Fit the Crops | F34: Kaitlyn's Puzzle | H34: Drew wins Safety | J34: BB Wiki
A35: BB28 | B35: Week 8 | C35: 52-53 | D35: Hit The Road | E35: Deliver the Grapes | F35: Berry Balanced | H35: Barrett wins Safety | J35: BB Wiki
A36: BB28 | B36: Week 8 | C36: 52-53 | D36: Hit The Road | E36: Adorn the Crown | F36: Hourglass | H36: Yash wins Safety | J36: BB Wiki
A37: BB28 | B37: Week 8 | C37: 53 | D37: HOH | E37: 2026: A Zing Odyssey | F37: Zingbot Competition | G37: Mental | H37: Drew wins HOH | I37: 1 | J37: BB Wiki
A38: BB28 | B38: Week 8 | C38: 54 | D38: POV | E38: The Gold, the Bad, and the Ugly | F38: Seesaw | G38: Physical | H38: Yash wins the Veto | I38: 1 | J38: BB Wiki
A39: BB28 | B39: Week 8 | C39: 59 | D39: Block Buster | E39: Your Game in Ruins | F39: Big Top Drop | H39: Devens is saved | J39: BB Wiki
A40: BB28 | B40: Week 9 | C40: 59 | D40: HOH | E40: Rainbow Rollers | F40: Perfect Shot | G40: Skill | H40: Barrett wins HOH | I40: 1 | J40: BB Wiki
...

Sheet Have-Nots
A1: Season | B1: Week | C1: Have-Not | D1: Made a Have-Not by | E1: Source | F1: Looks right? | G1: Correction
A2: BB28 | B2: Week 1 | C2: Devens | E2: BB Wiki
A3: BB28 | B3: Week 1 | C3: Drew | E3: BB Wiki
A4: BB28 | B4: Week 1 | C4: Taylor | E4: BB Wiki
A5: BB28 | B5: Week 1 | C5: Haley | E5: BB Wiki
A6: BB28 | B6: Week 1 | C6: Chuk | E6: BB Wiki
A7: BB28 | B7: Week 2 | C7: Barrett | E7: BB Wiki
A8: BB28 | B8: Week 2 | C8: Kamu | E8: BB Wiki
A9: BB28 | B9: Week 2 | C9: Lyric | E9: BB Wiki
A10: BB28 | B10: Week 2 | C10: Jason | E10: BB Wiki
A11: BB28 | B11: Week 2 | C11: Rome | E11: BB Wiki
A12: BB28 | B12: Week 3 | C12: Dee | E12: BB Wiki
A13: BB28 | B13: Week 3 | C13: Melody | E13: BB Wiki
... A30: BB28 | B30: Week 10 | C30: Devens | E30: BB Wiki
A31: BB27 | B31: Week 1 | C31: Ava | D31: Zach | E31: BB Wiki
A32: BB27 | B32: Week 1 | C32: Rachel | E32: BB Wiki
A33: BB27 | B33: Week 1 | C33: Will | D33: Rachel | E33: BB Wiki
A34: BB27 | B34: Week 1 | C34: Zach | D34: Will | E34: BB Wiki
A35: BB27 | B35: Week 2 | C35: Mickey | E35: BB Wiki
A36: BB27 | B36: Week 2 | C36: Rachel | E36: BB Wiki
A37: BB27 | B37: Week 2 | C37: Amy | E37: BB Wiki
A38: BB27 | B38: Week 3 | C38: Katherine | D38: Rachel | E38: BB Wiki
A39: BB27 | B39: Week 3 | C39: Jimmy | D39: Mickey | E39: BB Wiki
A40: BB27 | B40: Week 7 | C40: Ashley | E40: BB Wiki
A41: BB27 | B41: Week 7 | C41: Morgan | E41: BB Wiki
A42: BB27 | B42: Week 7 | C42: Will | E42: BB Wiki
A43: BB27 | B43: Week 8 | C43: Ava | D43: Ashley | E43: BB Wiki
A44: BB27 | B44: Week 8 | C44: Lauren | D44: Morgan | E44: BB Wiki
A45: BB27 | B45: Week 8 | C45: Vince | D45: Will | E45: BB Wiki
A46: BB26 | B46: Week 1 | C46: Cam | E46: BB Wiki
A47: BB26 | B47: Week 1 | C47: Kimo | E47: BB Wiki
A48: BB26 | B48: Week 1 | C48: Quinn | E48: BB Wiki
A49: BB26 | B49: Week 1 | C49: Tucker | E49: BB Wiki
A50: BB26 | B50: Week 2 | C50: Leah | E50: BB Wiki
A51: BB26 | B51: Week 2 | C51: Makensy | E51: BB Wiki
A52: BB26 | B52: Week 2 | C52: Rubina | E52: BB Wiki
A53: BB26 | B53: Week 2 | C53: Lisa | E53: BB Wiki
A54: BB26 | B54: Week 5 | C54: Angela | E54: BB Wiki
A55: BB26 | B55: Week 5 | C55: Joseph | E55: BB Wiki
A56: BB26 | B56: Week 5 | C56: Kimo | E56: BB Wiki
...

Sheet Bios
A1: Season | B1: Player | C1: Full name | D1: Age | E1: Born | F1: Hometown | G1: Occupation | H1: Days | I1: Alliances | J1: Source | K1: Looks right? | L1: Correction
A2: BB28 | B2: Devens | C2: Patrick William "Rick" Devens | D2: 42 | E2: 30777 | F2: Macon, Georgia | G2: Communications director | H2: 87 | I2: Bermuda Triangle, Mosh Pit, The Crossovers, The Culture, The Dapper Dans, The Icons, The Primaries, The Red Corner, The Toolshed, The Wolfpack | J2: BB Wiki
A3: BB28 | B3: Taylor | C3: Taylor Brown | D3: 27 | E3: 36067 | F3: Deerfield Beach, Florida | G3: School counselor | H3: 87 | I3: The Ceasefire, The Covenant, The Culture, The Honor Society, The Primaries | J3: BB Wiki
A4: BB28 | B4: Drew | C4: Drew Campbell | D4: 22 | E4: 38021 | F4: Temecula, California | G4: Surgical dental assistant | H4: 87 | I4: 4 Seasons, F.A.P., Melodrew, Mosh Pit, The Ceasefire, The Court Jesters, The Crossovers, The Dapper Dans, The Handymen, The Jugglers, The Toolshed | J4: BB Wiki
A5: BB28 | B5: Dee | C5: Dianelys Maria "Dee" Valladares | D5: 29 | E5: 35340 | F5: Miami, Florida | G5: Entrepreneur | H5: 80 | I5: Café con Leche, Mosh Pit, The Crossovers, The Culture, The Honor Society, The Icons, The Red Corner, The Toolshed, The Wolfpack | J5: BB Wiki
A6: BB28 | B6: Melody | C6: Melody Morris | D6: 24 | F6: Phoenix, Arizona | G6: Corporate game show host | H6: 77 | I6: 4 Seasons, F.A.P., Giggle Girls, Melodrew, Mosh Pit, Sirens, The Ceasefire, The Court Jesters | J6: BB Wiki
A7: BB28 | B7: Yash | C7: Yash Patel | D7: 24 | F7: Monroe Township, New Jersey | G7: Finance analyst | H7: 73 | I7: Bermuda Triangle, The Ceasefire, The Covenant, The Culture, The Dapper Dans, The Wolfpack | J7: BB Wiki
A8: BB28 | B8: Barrett | C8: Barrett Pfeiffer | D8: 27 | E8: 36047 | F8: Austin, Texas | G8: Jumbotron engineer | H8: 73 | I8: F.A.P., Mosh Pit, The Ceasefire, The Crossovers, The Dapper Dans, The Jugglers, The Toolshed | J8: BB Wiki
A9: BB28 | B9: Angela | C9: Angela Lorraine Murray | D9: 52 | E9: 26893 | F9: Syracuse, Utah | G9: Real estate agent | H9: 66 | I9: Mosh Pit, The Crossovers, The Honor Society, The Icons, The Toolshed | J9: BB Wiki
A10: BB28 | B10: La Trice | C10: LaTrice Verrett | D10: 57 | E10: 25033 | F10: Maplewood, New Jersey | G10: Boutique salesperson | H10: 59 | I10: Mama's Angels, The Covenant, The Honor Society | J10: BB Wiki
A11: BB28 | B11: Haley | C11: Haley Jordan Thogmartin | D11: 29 | E11: 35320 | F11: Wildwood, Missouri | G11: Telemedicine executive | H11: 53 | I11: The Red Corner, The Toolshed | J11: BB Wiki
A12: BB28 | B12: Mallory | C12: Mallory Aurichio | D12: 24 | F12: Washington Township, New Jersey | G12: Rocket scientist | H12: 52 | I12: F.A.P., Giggle Girls, Mosh Pit | J12: BB Wiki
A13: BB28 | B13: Kamu | C13: Gabriel Xavier Kamuela "Kamu" Kirk | D13: 32 | E13: 34437 | F13: Phoenix, Arizona | G13: MMA fighter | H13: 45 | I13: Bermuda Triangle, The Covenant, The Handymen, The Primaries, The Red Corner, The Toolshed, The Wolfpack | J13: BB Wiki
A14: BB28 | B14: Chuk | C14: Chukwuemeka "Chuk" Anyanwu | D14: 27 | F14: Dallas, Texas | G14: Supply chain analyst | H14: 38 | I14: The Red Corner, The Toolshed | J14: BB Wiki
A15: BB28 | B15: Lyric | C15: Lyric Leolani Medeiros | D15: 25 | E15: 37012 | F15: Honolulu, Hawaii | G15: Attorney | H15: 31 | I15: 4 Seasons, Giggle Girls, Sirens, The Love Triangle | J15: BB Wiki
A16: BB28 | B16: Jason | C16: Jason De Puy | D16: 35 | E16: 33154 | F16: Los Angeles, California | G16: Drag queen | H16: 24 | I16: Café con Leche, Mama's Angels, The Court Jesters, The Love Triangle | J16: BB Wiki
A17: BB28 | B17: Rome | C17: Jack "Rome" Seymour | D17: 28 | F17: Delray Beach, Florida | G17: Pickleball coach | H17: 17 | I17: 4 Seasons, Mama's Angels, The Love Triangle | J17: BB Wiki
A18: BB28 | B18: Ashley | C18: Ashley Trail | D18: 24 | E18: 37279 | F18: Chicago, Illinois | G18: Bartender | H18: 10 | J18: BB Wiki
A19: BB27 | B19: Ashley | C19: Ashley Diane Hollis | D19: 25 | E19: 36497 | F19: New York City, New York | G19: Attorney | H19: 83 | I19: Girls Girls (BB27), Peach Cobbler, The Judges, Will's Daughters | J19: BB Wiki
A20: BB27 | B20: Vince | C20: Vincent Frank "Vince" Panaro | D20: 34 | E20: 33340 | F20: West Hills, California | G20: Unemployed | H20: 83 | I20: Burger Boys, Heavy Hitters, Strong Side, The Bond, The Judges, The Melting Pot, The Night Owls, The Unexpendables, Triplets | J20: BB Wiki
A21: BB27 | B21: Morgan | C21: Morgan Leigh Pope | D21: 33 | E21: 33502 | F21: Los Angeles, California | G21: Gamer | H21: 83 | I21: Heavy Hitters, Strong Side, Tea Party, The Judges, The Melting Pot, The Night Owls, Triple Threat (BB27) | J21: BB Wiki
A22: BB27 | B22: Ava | C22: Ava Marie Pearl | D22: 24 | E22: 37048 | F22: Manhattan, New York | G22: Aura painter | H22: 80 | I22: Bond Girls, Double the Fun, Flower Power, The Bond, Will's Daughters | J22: BB Wiki
A23: BB27 | B23: Keanu | C23: Keanu Rey Soto | D23: 33 | E23: 33742 | F23: McKinney, Texas | G23: Dungeon Master | H23: 77 | I23: The Frenemies, The Unexpendables | J23: BB Wiki
A24: BB27 | B24: Lauren | C24: Lauren Elizabeth Domingue | D24: 22 | E24: 37492 | F24: Lafayette, Louisiana | G24: Bridal stylist | H24: 73 | I24: Bond Girls, Flower Power, The Bond | J24: BB Wiki
A25: BB27 | B25: Kelley | C25: Kelley Anna-Noreen Jorgensen | D25: 29 | E25: 34916 | F25: Burbank, South Dakota | G25: Web designer | H25: 73 | I25: Flower Power | J25: BB Wiki
A26: BB27 | B26: Will | C26: Cliffton Leonard "Will" Williams | D26: 50 | E26: 27550 | F26: Charlotte, North Carolina | G26: College sports podcaster | H26: 66 | I26: Burger Boys, Peach Cobbler, The Bond, The Judges | J26: BB Wiki
A27: BB27 | B27: Rachel | C27: Rachel Eileen Villegas | D27: 40 | E27: 30971 | F27: Hoover, Alabama | G27: TV personality | H27: 60 | I27: Double the Fun, Girls Girls (BB27), Heavy Hitters, The Frenemies, The Judges, The Mom Squad (BB27), Triplets | J27: BB Wiki
A28: BB27 | B28: Mickey | C28: Michaela Chalon "Mickey" Lee | D28: 35 | F28: Atlanta, Georgia | G28: Event curator | H28: 59 | I28: Peach Cobbler, Tea Party, The Melting Pot, Triple Threat (BB27) | J28: BB Wiki
A29: BB27 | B29: Katherine | C29: Katherine Elizabeth Woodman | D29: 23 | E29: 37281 | F29: Columbia, South Carolina | G29: Fine dining server | H29: 52 | J29: BB Wiki
A30: BB27 | B30: Rylie | C30: Rylie Don Jeffries | D30: 27 | E30: 35835 | F30: Luther, Oklahoma | G30: Professional bull rider | H30: 45 | I30: Burger Boys, Heavy Hitters, The Unexpendables | J30: BB Wiki
A31: BB27 | B31: Zach | C31: Zachary Senot "Zach" Cornell | D31: 27 | E31: 35782 | F31: Cartersville, Georgia | G31: Marketing manager | H31: 38 | I31: Burger Boys, Heavy Hitters, Strong Side, The Bond, The Melting Pot | J31: BB Wiki
A32: BB27 | B32: Jimmy | C32: James Jude "Jimmy" Heagerty III | D32: 25 | E32: 36437 | F32: Washington, D.C. | G32: Strategy consultant | H32: 31 | I32: Heavy Hitters, Triple Threat (BB27), Triplets | J32: BB Wiki
A33: BB27 | B33: Adrian | C33: Adrian Rocha | D33: 23 | E33: 37111 | F33: San Antonio, Texas | G33: Carpenter | H33: 24 | I33: The Bond | J33: BB Wiki
A34: BB27 | B34: Amy | C34: Amy Marian Bingham | D34: 43 | E34: 30013 | F34: Stockton, California | G34: Insurance agent | H34: 17 | I34: Girls Girls (BB27), The Mom Squad (BB27) | J34: BB Wiki
A35: BB27 | B35: Zae | C35: Isaiah Montgomery "Zae" Frederich | D35: 23 | E35: 37384 | F35: Provo, Utah | G35: Salesperson | H35: 10 | I35: Burger Boys | J35: BB Wiki
A36: BB26 | B36: Chelsie | C36: Chelsie Marlene Baham | D36: 27 | E36: 35427 | F36: Rancho Cucamonga, California | G36: Nonprofit director | H36: 90 | I36: The Barbershop, The Collective, The Core, The Pentagon, Final Three (BB26) | J36: BB Wiki
A37: BB26 | B37: Makensy | C37: Makensy Jo Manbeck | D37: 22 | E37: 37361 | F37: Houston, Texas | G37: Construction project manager | H37: 90 | I37: The Barbershop, Final Three (BB26) | J37: BB Wiki
A38: BB26 | B38: Cam | C38: Cameron "Cam" Sullivan-Brown | D38: 25 | E38: 36142 | F38: Bowie, Maryland | G38: Physical therapist | H38: 90 | I38: The Andersons, The Barbershop, The Collective, The Core, The Pentagon, Final Three (BB26) | J38: BB Wiki
A39: BB26 | B39: Rubina | C39: Rubina Ann Bernabe | D39: 35 | E39: 32543 | F39: Los Angeles, California | G39: Event bartender | H39: 87 | I39: 5 Pointz, The Trio, Sixth Avenue, The Barbershop, Tubina | J39: BB Wiki
A40: BB26 | B40: Kimo | C40: Kimo Apaka | D40: 35 | E40: 32403 | F40: Hilo, Hawaii | G40: Mattress sales representative | H40: 80 | I40: Five Pointz, The Trio, Sixth Avenue, The Andersons, The Collective, The Crow Boys, The Visionaries | J40: BB Wiki
...

Sheet Sources disagree
A1: Season | B1: Week | C1: Round | D1: Field | E1: Wikipedia | F1: Big Brother Wiki | G1: Source | H1: Looks right? | I1: Correction
A2: BB26 | B2: Week 3 | C2: 1 | D2: Initial nominations | E2: Angela, Kenney, Tucker | F2: Kenney, Makensy, Tucker | G2: BB Wiki
A3: BB26 | B3: Week 3 | C3: 1 | D3: Veto winner | E3: Tucker, Makensy | F3: Makensy | G3: BB Wiki
A4: BB25 | B4: Week 1 | C4: 1 | D4: Initial nominations | E4: Cory, Felicia, Jared, Kirsten | F4: Jared, Kirsten | G4: BB Wiki
A5: BB25 | B5: Week 1 | C5: 1 | D5: Veto used | E5: Yes | F5: No | G5: BB Wiki
A6: BB23 | B6: Week 7 | C6: 1 | D6: Initial nominations | E6: Claire, Derek F., Xavier | F6: Claire, Xavier | G6: BB Wiki
A7: BB23 | B7: Week 8 | C7: 1 | D7: HOH | E7: Tiffany, Claire | F7: Claire | G7: BB Wiki
A8: BB22 | B8: Week 6 | C8: 1 | D8: Initial nominations | E8: David, Kevin, Tyler | F8: Kevin, Tyler | G8: BB Wiki

Sheet What was different
A1: Season | B1: Week | C1: Type | D1: Text | E1: Source | F1: Looks right? | G1: Correction
A2: BB28 | B2: Week 1 | C2: Twist / outcome | D2: Block Buster: Yash | E2: Wikipedia
A3: BB28 | B3: Week 1 | C3: Wikipedia note [e] | D3: This HouseGuest won the BB Block Buster competition and was saved from possible eviction. | E3: Wikipedia
A4: BB28 | B4: Week 1 | C4: Wikipedia note [i] | D4: This HouseGuest won a competition and was immune from eviction. | E4: Wikipedia
A5: BB28 | B5: Week 2 | C5: Twist / outcome | D5: Block Buster: Jason | E5: Wikipedia
A6: BB28 | B6: Week 2 | C6: Wikipedia note [e] | D6: This HouseGuest won the BB Block Buster competition and was saved from possible eviction. | E6: Wikipedia
